Workbook

Sheet Dashboard
B1: APP FACTORY · BUILD DASHBOARD
B2: Read-only. Every figure is a formula off the four track sheets - change a Status there and this updates.
B4: WHERE YOU ARE · everything combined
B5: Level | C5: =INDEX(Config!$B$19:$B$26,Config!$C$15) -> 3. Draughtsman
B6: XP earned | C6: =Config!$C$14 -> 337
B7: Total plan XP | C7: =Config!$C$13 -> 993
B8: XP to next level | C8: =IF(Config!$C$15>=8,0,INDEX(Config!$D$19:$D$26,Config!$C$15+1)-Config!$C$14) -> 1
B9: Next level | C9: =IF(Config!$C$15>=8,"- max level -",INDEX(Config!$B$19:$B$26,Config!$C$15+1)) -> 4. Engineer
B10: Overall completion | C10: =IFERROR(Config!$C$14/Config!$C$13,0) -> 0.33937563 | F10: =REPT("█",ROUND($C$10*20,0))&REPT("░",20-ROUND($C$10*20,0)) -> ███████░░░░░░░░░░░░░
B11: Tasks done | C11: =COUNTIF(Setup!$H$3:$H$62,"Done")+COUNTIF('App 1'!$H$3:$H$31,"Done")+COUNTIF('App 2'!$H$3:$H$11,"Done")+COUNTIF(Documentation!$H$3:$H$19,"Done")&" of "&COUNTA(Setup!$B$3:$B$62)+COUNTA('App 1'!$B$3:$B$31)+COUNTA('App 2'!$B$3:$B$11)+COUNTA(Documentation!$B$3:$B$19) -> 44 of 115
B12: Hours of your time remaining | C12: =ROUND((SUMIFS(Setup!$E$3:$E$62,Setup!$H$3:$H$62,"<>Done")+SUMIFS('App 1'!$E$3:$E$31,'App 1'!$H$3:$H$31,"<>Done")+SUMIFS('App 2'!$E$3:$E$11,'App 2'!$H$3:$H$11,"<>Done")+SUMIFS(Documentation!$E$3:$E$19,Documentation!$H$3:$H$19,"<>Done"))/60,1) -> 47.1
B13: Next up, right now | C13: =IF($D$18<$C$18,$C$35,IF($D$19<$C$19,$C$44,IF($D$20<$C$20,$C$52,IF($D$21<$C$21,$C$61,"Everything is done. Go outside.")))) -> 5.1 · Open the Routines dashboard
B15: TRACKS · the four pages, side by side
B16: Setup is the only one that matters today. The rest are here so you know they exist.
B17: Track | C17: Tasks | D17: Done | E17: % | F17: Progress | G17: Hours left
B18: Setup | C18: =COUNTA(Setup!$B$3:$B$62) -> 60 | D18: =COUNTIF(Setup!$H$3:$H$62,"Done") -> 44 | E18: =IFERROR($D18/$C18,0) -> 0.73333333 | F18: =REPT("█",ROUND($E18*20,0))&REPT("░",20-ROUND($E18*20,0)) -> ███████████████░░░░░ | G18: =ROUND(SUMIFS(Setup!$E$3:$E$62,Setup!$H$3:$H$62,"<>Done")/60,1) -> 7.4
B19: App 1 | C19: =COUNTA('App 1'!$B$3:$B$31) -> 29 | D19: =COUNTIF('App 1'!$H$3:$H$31,"Done") -> 0 | E19: =IFERROR($D19/$C19,0) -> 0 | F19: =REPT("█",ROUND($E19*20,0))&REPT("░",20-ROUND($E19*20,0)) -> ░░░░░░░░░░░░░░░░░░░░ | G19: =ROUND(SUMIFS('App 1'!$E$3:$E$31,'App 1'!$H$3:$H$31,"<>Done")/60,1) -> 20.5
B20: App 2 | C20: =COUNTA('App 2'!$B$3:$B$11) -> 9 | D20: =COUNTIF('App 2'!$H$3:$H$11,"Done") -> 0 | E20: =IFERROR($D20/$C20,0) -> 0 | F20: =REPT("█",ROUND($E20*20,0))&REPT("░",20-ROUND($E20*20,0)) -> ░░░░░░░░░░░░░░░░░░░░ | G20: =ROUND(SUMIFS('App 2'!$E$3:$E$11,'App 2'!$H$3:$H$11,"<>Done")/60,1) -> 6.4
B21: Documentation | C21: =COUNTA(Documentation!$B$3:$B$19) -> 17 | D21: =COUNTIF(Documentation!$H$3:$H$19,"Done") -> 0 | E21: =IFERROR($D21/$C21,0) -> 0 | F21: =REPT("█",ROUND($E21*20,0))&REPT("░",20-ROUND($E21*20,0)) -> ░░░░░░░░░░░░░░░░░░░░ | G21: =ROUND(SUMIFS(Documentation!$E$3:$E$19,Documentation!$H$3:$H$19,"<>Done")/60,1) -> 12.8
B23: SETUP · individual view
B24: Getting the factory running. This is the only track that matters right now.
B25: Phase | C25: Tasks | D25: Done | E25: % | F25: Progress | G25: Hours left
B26: =Config!$B$35 -> Phase 0 · Design review | C26: =COUNTIF(Setup!$A$3:$A$62,$B26) -> 3 | D26: =COUNTIFS(Setup!$A$3:$A$62,$B26,Setup!$H$3:$H$62,"Done") -> 3 | E26: =IFERROR($D26/$C26,0) -> 1 | F26: =REPT("█",ROUND($E26*20,0))&REPT("░",20-ROUND($E26*20,0)) -> ████████████████████ | G26: =ROUND(SUMIFS(Setup!$E$3:$E$62,Setup!$A$3:$A$62,$B26,Setup!$H$3:$H$62,"<>Done")/60,1) -> 0
B27: =Config!$B$36 -> Phase 1 · Environment check | C27: =COUNTIF(Setup!$A$3:$A$62,$B27) -> 6 | D27: =COUNTIFS(Setup!$A$3:$A$62,$B27,Setup!$H$3:$H$62,"Done") -> 6 | E27: =IFERROR($D27/$C27,0) -> 1 | F27: =REPT("█",ROUND($E27*20,0))&REPT("░",20-ROUND($E27*20,0)) -> ████████████████████ | G27: =ROUND(SUMIFS(Setup!$E$3:$E$62,Setup!$A$3:$A$62,$B27,Setup!$H$3:$H$62,"<>Done")/60,1) -> 0
B28: =Config!$B$37 -> Phase 2 · Provisional v0.1 assets | C28: =COUNTIF(Setup!$A$3:$A$62,$B28) -> 12 | D28: =COUNTIFS(Setup!$A$3:$A$62,$B28,Setup!$H$3:$H$62,"Done") -> 12 | E28: =IFERROR($D28/$C28,0) -> 1 | F28: =REPT("█",ROUND($E28*20,0))&REPT("░",20-ROUND($E28*20,0)) -> ████████████████████ | G28: =ROUND(SUMIFS(Setup!$E$3:$E$62,Setup!$A$3:$A$62,$B28,Setup!$H$3:$H$62,"<>Done")/60,1) -> 0
B29: =Config!$B$38 -> Phase 3 · Infrastructure setup | C29: =COUNTIF(Setup!$A$3:$A$62,$B29) -> 16 | D29: =COUNTIFS(Setup!$A$3:$A$62,$B29,Setup!$H$3:$H$62,"Done") -> 16 | E29: =IFERROR($D29/$C29,0) -> 1 | F29: =REPT("█",ROUND($E29*20,0))&REPT("░",20-ROUND($E29*20,0)) -> ████████████████████ | G29: =ROUND(SUMIFS(Setup!$E$3:$E$62,Setup!$A$3:$A$62,$B29,Setup!$H$3:$H$62,"<>Done")/60,1) -> 0
B30: =Config!$B$39 -> Phase 4 · Agent & skill definitions | C30: =COUNTIF(Setup!$A$3:$A$62,$B30) -> 7 | D30: =COUNTIFS(Setup!$A$3:$A$62,$B30,Setup!$H$3:$H$62,"Done") -> 7 | E30: =IFERROR($D30/$C30,0) -> 1 | F30: =REPT("█",ROUND($E30*20,0))&REPT("░",20-ROUND($E30*20,0)) -> ████████████████████ | G30: =ROUND(SUMIFS(Setup!$E$3:$E$62,Setup!$A$3:$A$62,$B30,Setup!$H$3:$H$62,"<>Done")/60,1) -> 0
B31: =Config!$B$40 -> Phase 5 · Configure the routine | C31: =COUNTIF(Setup!$A$3:$A$62,$B31) -> 6 | D31: =COUNTIFS(Setup!$A$3:$A$62,$B31,Setup!$H$3:$H$62,"Done") -> 0 | E31: =IFERROR($D31/$C31,0) -> 0 | F31: =REPT("█",ROUND($E31*20,0))&REPT("░",20-ROUND($E31*20,0)) -> ░░░░░░░░░░░░░░░░░░░░ | G31: =ROUND(SUMIFS(Setup!$E$3:$E$62,Setup!$A$3:$A$62,$B31,Setup!$H$3:$H$62,"<>Done")/60,1) -> 2.3
B32: =Config!$B$41 -> Phase 6 · Smoke test | C32: =COUNTIF(Setup!$A$3:$A$62,$B32) -> 10 | D32: =COUNTIFS(Setup!$A$3:$A$62,$B32,Setup!$H$3:$H$62,"Done") -> 0 | E32: =IFERROR($D32/$C32,0) -> 0 | F32: =REPT("█",ROUND($E32*20,0))&REPT("░",20-ROUND($E32*20,0)) -> ░░░░░░░░░░░░░░░░░░░░ | G32: =ROUND(SUMIFS(Setup!$E$3:$E$62,Setup!$A$3:$A$62,$B32,Setup!$H$3:$H$62,"<>Done")/60,1) -> 5.1
B33: Setup - all phases | C33: =COUNTA(Setup!$B$3:$B$62) -> 60 | D33: =COUNTIF(Setup!$H$3:$H$62,"Done") -> 44 | E33: =IFERROR($D33/$C33,0) -> 0.73333333 | F33: =REPT("█",ROUND($E33*20,0))&REPT("░",20-ROUND($E33*20,0)) -> ███████████████░░░░░ | G33: =ROUND(SUMIFS(Setup!$E$3:$E$62,Setup!$H$3:$H$62,"<>Done")/60,1) -> 7.4
B34: XP in this track | C34: =SUMIFS(Setup!$G$3:$G$62,Setup!$H$3:$H$62,"Done")&" / "&SUM(Setup!$G$3:$G$62) -> 337 / 455
B35: Next up in this track | C35: =IFERROR(INDEX(Setup!$B$3:$B$62,MATCH(MIN(Setup!$L$3:$L$62),Setup!$L$3:$L$62,0))&" · "&INDEX(Setup!$C$3:$C$62,MATCH(MIN(Setup!$L$3:$L$62),Setup!$L$3:$L$62,0)),"- nothing available in this track -") -> 5.1 · Open the Routines dashboard
B37: APP 1 · individual view
B38: Build FPL through the pipeline, then rewrite the assets from what actually happened.
B39: Phase | C39: Tasks | D39: Done | E39: % | F39: Progress | G39: Hours left
B40: =Config!$B$42 -> Phase 7 · Build app #1 (FPL) | C40: =COUNTIF('App 1'!$A$3:$A$31,$B40) -> 18 | D40: =COUNTIFS('App 1'!$A$3:$A$31,$B40,'App 1'!$H$3:$H$31,"Done") -> 0 | E40: =IFERROR($D40/$C40,0) -> 0 | F40: =REPT("█",ROUND($E40*20,0))&REPT("░",20-ROUND($E40*20,0)) -> ░░░░░░░░░░░░░░░░░░░░ | G40: =ROUND(SUMIFS('App 1'!$E$3:$E$31,'App 1'!$A$3:$A$31,$B40,'App 1'!$H$3:$H$31,"<>Done")/60,1) -> 11.3
B41: =Config!$B$43 -> Phase 8 · Retrospective & asset revision | C41: =COUNTIF('App 1'!$A$3:$A$31,$B41) -> 11 | D41: =COUNTIFS('App 1'!$A$3:$A$31,$B41,'App 1'!$H$3:$H$31,"Done") -> 0 | E41: =IFERROR($D41/$C41,0) -> 0 | F41: =REPT("█",ROUND($E41*20,0))&REPT("░",20-ROUND($E41*20,0)) -> ░░░░░░░░░░░░░░░░░░░░ | G41: =ROUND(SUMIFS('App 1'!$E$3:$E$31,'App 1'!$A$3:$A$31,$B41,'App 1'!$H$3:$H$31,"<>Done")/60,1) -> 9.3
B42: App 1 - all phases | C42: =COUNTA('App 1'!$B$3:$B$31) -> 29 | D42: =COUNTIF('App 1'!$H$3:$H$31,"Done") -> 0 | E42: =IFERROR($D42/$C42,0) -> 0 | F42: =REPT("█",ROUND($E42*20,0))&REPT("░",20-ROUND($E42*20,0)) -> ░░░░░░░░░░░░░░░░░░░░ | G42: =ROUND(SUMIFS('App 1'!$E$3:$E$31,'App 1'!$H$3:$H$31,"<>Done")/60,1) -> 20.5
B43: XP in this track | C43: =SUMIFS('App 1'!$G$3:$G$31,'App 1'!$H$3:$H$31,"Done")&" / "&SUM('App 1'!$G$3:$G$31) -> 0 / 272
B44: Next up in this track | C44: =IFERROR(INDEX('App 1'!$B$3:$B$31,MATCH(MIN('App 1'!$L$3:$L$31),'App 1'!$L$3:$L$31,0))&" · "&INDEX('App 1'!$C$3:$C$31,MATCH(MIN('App 1'!$L$3:$L$31),'App 1'!$L$3:$L$31,0)),"- nothing available in this track -") -> - nothing available in this track -
...

Sheet Setup
A1: SETUP | C1: Getting the factory running. This is the only track that matters right now.
A2: Phase | B2: Task ID | C2: Task | D2: What "done" looks like | E2: Est. time (mins) | F2: Difficulty (1-5) | G2: XP | H2: Status | I2: Blocked by | J2: Notes | K2: Blocked? (auto) | L2: Queue rank (auto)
A3: Phase 0 · Design review | B3: 0.1 | C3: Confirm the v2 design document is the single working reference | D3: app-factory-system-design-v2.md is saved in the factory repo and no other version is open on the desktop | E3: 15 | F3: 1 | G3: =IFERROR(INDEX(Config!$E$5:$E$9,MATCH($F3,Config!$D$5:$D$9,0)),0) -> 4 | H3: Done | J3: Phase 0 is marked done in the source plan — this row is pre-set to Done. | K3: =IF($I3="","No",IF(IFERROR(INDEX(Setup!$H$3:$H$62,MATCH($I3,Setup!$B$3:$B$62,0)),IFERROR(INDEX('App 1'!$H$3:$H$31,MATCH($I3,'App 1'!$B$3:$B$31,0)),IFERROR(INDEX('App 2'!$H$3:$H$11,MATCH($I3,'App 2'!$B$3:$B$11,0)),IFERROR(INDEX(Documentation!$H$3:$H$19,MATCH($I3,Documentation!$B$3:$B$19,0)),"Done"))))="Done","No","Yes")) -> No | L3: =IF(AND($H3<>"Done",$K3="No"),ROW(),"")
A4: Phase 0 · Design review | B4: 0.2 | C4: Re-verify current Claude Code Routines behaviour against §4.1 | D4: The Routines docs page has been read today and three facts are confirmed in writing: minimum interval, per-account daily run cap, and the claude/ branch push restriction | E4: 30 | F4: 2 | G4: =IFERROR(INDEX(Config!$E$5:$E$9,MATCH($F4,Config!$D$5:$D$9,0)),0) -> 7 | H4: Done | I4: 0.1 | J4: Risk #9: Routines is a research preview. Verify at build time, not from the doc. | K4: =IF($I4="","No",IF(IFERROR(INDEX(Setup!$H$3:$H$62,MATCH($I4,Setup!$B$3:$B$62,0)),IFERROR(INDEX('App 1'!$H$3:$H$31,MATCH($I4,'App 1'!$B$3:$B$31,0)),IFERROR(INDEX('App 2'!$H$3:$H$11,MATCH($I4,'App 2'!$B$3:$B$11,0)),IFERROR(INDEX(Documentation!$H$3:$H$19,MATCH($I4,Documentation!$B$3:$B$19,0)),"Done"))))="Done","No","Yes")) -> No | L4: =IF(AND($H4<>"Done",$K4="No"),ROW(),"")
A5: Phase 0 · Design review | B5: 0.3 | C5: Record any Routines deltas since 9 Aug 2026 | D5: A deltas.md file exists in the factory repo listing each difference found, or the single line 'no deltas, checked <date>' | E5: 20 | F5: 1 | G5: =IFERROR(INDEX(Config!$E$5:$E$9,MATCH($F5,Config!$D$5:$D$9,0)),0) -> 4 | H5: Done | I5: 0.2 | J5: If a delta breaks a design assumption, resolve it before Phase 4. | K5: =IF($I5="","No",IF(IFERROR(INDEX(Setup!$H$3:$H$62,MATCH($I5,Setup!$B$3:$B$62,0)),IFERROR(INDEX('App 1'!$H$3:$H$31,MATCH($I5,'App 1'!$B$3:$B$31,0)),IFERROR(INDEX('App 2'!$H$3:$H$11,MATCH($I5,'App 2'!$B$3:$B$11,0)),IFERROR(INDEX(Documentation!$H$3:$H$19,MATCH($I5,Documentation!$B$3:$B$19,0)),"Done"))))="Done","No","Yes")) -> No | L5: =IF(AND($H5<>"Done",$K5="No"),ROW(),"")
A6: Phase 1 · Environment check | B6: 1.1 | C6: Open Claude Code and run /status | D6: The /status output is on screen and reports the Pro plan | E6: 10 | F6: 1 | G6: =IFERROR(INDEX(Config!$E$5:$E$9,MATCH($F6,Config!$D$5:$D$9,0)),0) -> 4 | H6: Done | J6: §9 risk #2. Do this before anything else touches quota. | K6: =IF($I6="","No",IF(IFERROR(INDEX(Setup!$H$3:$H$62,MATCH($I6,Setup!$B$3:$B$62,0)),IFERROR(INDEX('App 1'!$H$3:$H$31,MATCH($I6,'App 1'!$B$3:$B$31,0)),IFERROR(INDEX('App 2'!$H$3:$H$11,MATCH($I6,'App 2'!$B$3:$B$11,0)),IFERROR(INDEX(Documentation!$H$3:$H$19,MATCH($I6,Documentation!$B$3:$B$19,0)),"Done"))))="Done","No","Yes")) -> No | L6: =IF(AND($H6<>"Done",$K6="No"),ROW(),"")
A7: Phase 1 · Environment check | B7: 1.2 | C7: Check the shell environment for a stray Anthropic API key | D7: `env | grep -i anthropic` has been run and its output (empty or not) has been read | E7: 15 | F7: 2 | G7: =IFERROR(INDEX(Config!$E$5:$E$9,MATCH($F7,Config!$D$5:$D$9,0)),0) -> 7 | H7: Done | I7: 1.1 | J7: A set ANTHROPIC_API_KEY silently bills the API instead of the subscription. | K7: =IF($I7="","No",IF(IFERROR(INDEX(Setup!$H$3:$H$62,MATCH($I7,Setup!$B$3:$B$62,0)),IFERROR(INDEX('App 1'!$H$3:$H$31,MATCH($I7,'App 1'!$B$3:$B$31,0)),IFERROR(INDEX('App 2'!$H$3:$H$11,MATCH($I7,'App 2'!$B$3:$B$11,0)),IFERROR(INDEX(Documentation!$H$3:$H$19,MATCH($I7,Documentation!$B$3:$B$19,0)),"Done"))))="Done","No","Yes")) -> No | L7: =IF(AND($H7<>"Done",$K7="No"),ROW(),"")
A8: Phase 1 · Environment check | B8: 1.3 | C8: Unset any stray API key found, in the shell and in the shell profile | D8: `env | grep -i anthropic` returns nothing in a brand-new terminal window | E8: 20 | F8: 2 | G8: =IFERROR(INDEX(Config!$E$5:$E$9,MATCH($F8,Config!$D$5:$D$9,0)),0) -> 7 | H8: Done | I8: 1.2 | J8: Skip and mark Done if 1.2 found nothing. Check ~/.zshrc and ~/.zprofile. | K8: =IF($I8="","No",IF(IFERROR(INDEX(Setup!$H$3:$H$62,MATCH($I8,Setup!$B$3:$B$62,0)),IFERROR(INDEX('App 1'!$H$3:$H$31,MATCH($I8,'App 1'!$B$3:$B$31,0)),IFERROR(INDEX('App 2'!$H$3:$H$11,MATCH($I8,'App 2'!$B$3:$B$11,0)),IFERROR(INDEX(Documentation!$H$3:$H$19,MATCH($I8,Documentation!$B$3:$B$19,0)),"Done"))))="Done","No","Yes")) -> No | L8: =IF(AND($H8<>"Done",$K8="No"),ROW(),"")
A9: Phase 1 · Environment check | B9: 1.4 | C9: Confirm the GitHub CLI is authenticated | D9: `gh auth status` prints 'Logged in to github.com' for the intended account | E9: 10 | F9: 1 | G9: =IFERROR(INDEX(Config!$E$5:$E$9,MATCH($F9,Config!$D$5:$D$9,0)),0) -> 4 | H9: Done | J9: Already installed per §2; this is a confirmation, not a setup step. | K9: =IF($I9="","No",IF(IFERROR(INDEX(Setup!$H$3:$H$62,MATCH($I9,Setup!$B$3:$B$62,0)),IFERROR(INDEX('App 1'!$H$3:$H$31,MATCH($I9,'App 1'!$B$3:$B$31,0)),IFERROR(INDEX('App 2'!$H$3:$H$11,MATCH($I9,'App 2'!$B$3:$B$11,0)),IFERROR(INDEX(Documentation!$H$3:$H$19,MATCH($I9,Documentation!$B$3:$B$19,0)),"Done"))))="Done","No","Yes")) -> No | L9: =IF(AND($H9<>"Done",$K9="No"),ROW(),"")
A10: Phase 1 · Environment check | B10: 1.5 | C10: Update Claude Code and confirm the version | D10: `claude --version` prints a version, and it matches the latest release notes checked today | E10: 15 | F10: 1 | G10: =IFERROR(INDEX(Config!$E$5:$E$9,MATCH($F10,Config!$D$5:$D$9,0)),0) -> 4 | H10: Done | J10: Routines behaviour changes between versions. | K10: =IF($I10="","No",IF(IFERROR(INDEX(Setup!$H$3:$H$62,MATCH($I10,Setup!$B$3:$B$62,0)),IFERROR(INDEX('App 1'!$H$3:$H$31,MATCH($I10,'App 1'!$B$3:$B$31,0)),IFERROR(INDEX('App 2'!$H$3:$H$11,MATCH($I10,'App 2'!$B$3:$B$11,0)),IFERROR(INDEX(Documentation!$H$3:$H$19,MATCH($I10,Documentation!$B$3:$B$19,0)),"Done"))))="Done","No","Yes")) -> No | L10: =IF(AND($H10<>"Done",$K10="No"),ROW(),"")
A11: Phase 1 · Environment check | B11: 1.6 | C11: Write the environment baseline note | D11: environment-baseline.md exists in the factory repo with plan tier, Claude Code version, gh account and date | E11: 15 | F11: 1 | G11: =IFERROR(INDEX(Config!$E$5:$E$9,MATCH($F11,Config!$D$5:$D$9,0)),0) -> 4 | H11: Done | I11: 1.4 | J11: Also needs 1.1 finished. One paragraph. This is what you compare against when something breaks in week three. | K11: =IF($I11="","No",IF(IFERROR(INDEX(Setup!$H$3:$H$62,MATCH($I11,Setup!$B$3:$B$62,0)),IFERROR(INDEX('App 1'!$H$3:$H$31,MATCH($I11,'App 1'!$B$3:$B$31,0)),IFERROR(INDEX('App 2'!$H$3:$H$11,MATCH($I11,'App 2'!$B$3:$B$11,0)),IFERROR(INDEX(Documentation!$H$3:$H$19,MATCH($I11,Documentation!$B$3:$B$19,0)),"Done"))))="Done","No","Yes")) -> No | L11: =IF(AND($H11<>"Done",$K11="No"),ROW(),"")
A12: Phase 2 · Provisional v0.1 assets | B12: 2.1 | C12: Create the factory repo and the v0.1 assets folder | D12: A GitHub repo named app-factory exists with an /assets folder containing a README naming the four v0.1 assets | E12: 20 | F12: 1 | G12: =IFERROR(INDEX(Config!$E$5:$E$9,MATCH($F12,Config!$D$5:$D$9,0)),0) -> 4 | H12: Done | J12: The factory repo is separate from each app repo. It holds assets, the runbook and the explainer. | K12: =IF($I12="","No",IF(IFERROR(INDEX(Setup!$H$3:$H$62,MATCH($I12,Setup!$B$3:$B$62,0)),IFERROR(INDEX('App 1'!$H$3:$H$31,MATCH($I12,'App 1'!$B$3:$B$31,0)),IFERROR(INDEX('App 2'!$H$3:$H$11,MATCH($I12,'App 2'!$B$3:$B$11,0)),IFERROR(INDEX(Documentation!$H$3:$H$19,MATCH($I12,Documentation!$B$3:$B$19,0)),"Done"))))="Done","No","Yes")) -> No | L12: =IF(AND($H12<>"Done",$K12="No"),ROW(),"")
A13: Phase 2 · Provisional v0.1 assets | B13: 2.2 | C13: Draft the product brief template skeleton | D13: assets/product-brief-template.md exists with named, empty sections and a one-line instruction under each | E13: 40 | F13: 2 | G13: =IFERROR(INDEX(Config!$E$5:$E$9,MATCH($F13,Config!$D$5:$D$9,0)),0) -> 7 | H13: Done | I13: 2.1 | J13: §12. Explicitly rough — Phase 8 rewrites this from evidence. | K13: =IF($I13="","No",IF(IFERROR(INDEX(Setup!$H$3:$H$62,MATCH($I13,Setup!$B$3:$B$62,0)),IFERROR(INDEX('App 1'!$H$3:$H$31,MATCH($I13,'App 1'!$B$3:$B$31,0)),IFERROR(INDEX('App 2'!$H$3:$H$11,MATCH($I13,'App 2'!$B$3:$B$11,0)),IFERROR(INDEX(Documentation!$H$3:$H$19,MATCH($I13,Documentation!$B$3:$B$19,0)),"Done"))))="Done","No","Yes")) -> No | L13: =IF(AND($H13<>"Done",$K13="No"),ROW(),"")
A14: Phase 2 · Provisional v0.1 assets | B14: 2.3 | C14: Add the in-game currency Tier-3 declaration to the brief template | D14: The template contains a filled example line declaring in-game currency (FPL budgets, prices, 'bank') as Tier 3 | E14: 20 | F14: 2 | G14: =IFERROR(INDEX(Config!$E$5:$E$9,MATCH($F14,Config!$D$5:$D$9,0)),0) -> 7 | H14: Done | I14: 2.2 | J14: §3 note 3. Without this the Analyst blocks half the FPL backlog. | K14: =IF($I14="","No",IF(IFERROR(INDEX(Setup!$H$3:$H$62,MATCH($I14,Setup!$B$3:$B$62,0)),IFERROR(INDEX('App 1'!$H$3:$H$31,MATCH($I14,'App 1'!$B$3:$B$31,0)),IFERROR(INDEX('App 2'!$H$3:$H$11,MATCH($I14,'App 2'!$B$3:$B$11,0)),IFERROR(INDEX(Documentation!$H$3:$H$19,MATCH($I14,Documentation!$B$3:$B$19,0)),"Done"))))="Done","No","Yes")) -> No | L14: =IF(AND($H14<>"Done",$K14="No"),ROW(),"")
A15: Phase 2 · Provisional v0.1 assets | B15: 2.4 | C15: Add the personal-data section to the brief template | D15: The template has a 'What personal data this app may store' section with an explicit 'none' option | E15: 20 | F15: 2 | G15: =IFERROR(INDEX(Config!$E$5:$E$9,MATCH($F15,Config!$D$5:$D$9,0)),0) -> 7 | H15: Done | I15: 2.2 | J15: Tier 1 territory. Stating 'none' up front is what stops silent accretion. | K15: =IF($I15="","No",IF(IFERROR(INDEX(Setup!$H$3:$H$62,MATCH($I15,Setup!$B$3:$B$62,0)),IFERROR(INDEX('App 1'!$H$3:$H$31,MATCH($I15,'App 1'!$B$3:$B$31,0)),IFERROR(INDEX('App 2'!$H$3:$H$11,MATCH($I15,'App 2'!$B$3:$B$11,0)),IFERROR(INDEX(Documentation!$H$3:$H$19,MATCH($I15,Documentation!$B$3:$B$19,0)),"Done"))))="Done","No","Yes")) -> No | L15: =IF(AND($H15<>"Done",$K15="No"),ROW(),"")
A16: Phase 2 · Provisional v0.1 assets | B16: 2.5 | C16: Add the external data source field to the brief template | D16: The template has a 'Chosen external data source' field marked as a Tier-2 high-impact decision requiring a written 'because' | E16: 20 | F16: 2 | G16: =IFERROR(INDEX(Config!$E$5:$E$9,MATCH($F16,Config!$D$5:$D$9,0)),0) -> 7 | H16: Done | I16: 2.2 | J16: §3 note 1 — decide it deliberately in the brief, not by the Analyst at 3am. | K16: =IF($I16="","No",IF(IFERROR(INDEX(Setup!$H$3:$H$62,MATCH($I16,Setup!$B$3:$B$62,0)),IFERROR(INDEX('App 1'!$H$3:$H$31,MATCH($I16,'App 1'!$B$3:$B$31,0)),IFERROR(INDEX('App 2'!$H$3:$H$11,MATCH($I16,'App 2'!$B$3:$B$11,0)),IFERROR(INDEX(Documentation!$H$3:$H$19,MATCH($I16,Documentation!$B$3:$B$19,0)),"Done"))))="Done","No","Yes")) -> No | L16: =IF(AND($H16<>"Done",$K16="No"),ROW(),"")
A17: Phase 2 · Provisional v0.1 assets | B17: 2.6 | C17: Draft the ticket template with a definition-of-done field | D17: assets/ticket-template.md exists and contains a definition-of-done field plus at least one worked example ticket | E17: 45 | F17: 2 | G17: =IFERROR(INDEX(Config!$E$5:$E$9,MATCH($F17,Config!$D$5:$D$9,0)),0) -> 7 | H17: Done | I17: 2.1 | J17: §12: definition-of-done folded in from v1's separate template. | K17: =IF($I17="","No",IF(IFERROR(INDEX(Setup!$H$3:$H$62,MATCH($I17,Setup!$B$3:$B$62,0)),IFERROR(INDEX('App 1'!$H$3:$H$31,MATCH($I17,'App 1'!$B$3:$B$31,0)),IFERROR(INDEX('App 2'!$H$3:$H$11,MATCH($I17,'App 2'!$B$3:$B$11,0)),IFERROR(INDEX(Documentation!$H$3:$H$19,MATCH($I17,Documentation!$B$3:$B$19,0)),"Done"))))="Done","No","Yes")) -> No | L17: =IF(AND($H17<>"Done",$K17="No"),ROW(),"")
A18: Phase 2 · Provisional v0.1 assets | B18: 2.7 | C18: Draft a rough design-reference.md | D18: assets/design-reference.md lists 3-5 named references, each with one line saying what specifically to take from it | E18: 60 | F18: 3 | G18: =IFERROR(INDEX(Config!$E$5:$E$9,MATCH($F18,Config!$D$5:$D$9,0)),0) -> 11 | H18: Done | I18: 2.1 | J18: §5.3. Rough is fine here; distinctive is Phase 8's job. | K18: =IF($I18="","No",IF(IFERROR(INDEX(Setup!$H$3:$H$62,MATCH($I18,Setup!$B$3:$B$62,0)),IFERROR(INDEX('App 1'!$H$3:$H$31,MATCH($I18,'App 1'!$B$3:$B$31,0)),IFERROR(INDEX('App 2'!$H$3:$H$11,MATCH($I18,'App 2'!$B$3:$B$11,0)),IFERROR(INDEX(Documentation!$H$3:$H$19,MATCH($I18,Documentation!$B$3:$B$19,0)),"Done"))))="Done","No","Yes")) -> No | L18: =IF(AND($H18<>"Done",$K18="No"),ROW(),"")
A19: Phase 2 · Provisional v0.1 assets | B19: 2.8 | C19: Draft the Analyst subagent definition | D19: assets/agents/analyst.md exists and states the three escalation tiers verbatim plus the brief-first order of operations | E19: 50 | F19: 3 | G19: =IFERROR(INDEX(Config!$E$5:$E$9,MATCH($F19,Config!$D$5:$D$9,0)),0) -> 11 | H19: Done | I19: 2.1 | J19: §4.5. Must include Rule A: tiers classify decisions, not just questions. | K19: =IF($I19="","No",IF(IFERROR(INDEX(Setup!$H$3:$H$62,MATCH($I19,Setup!$B$3:$B$62,0)),IFERROR(INDEX('App 1'!$H$3:$H$31,MATCH($I19,'App 1'!$B$3:$B$31,0)),IFERROR(INDEX('App 2'!$H$3:$H$11,MATCH($I19,'App 2'!$B$3:$B$11,0)),IFERROR(INDEX(Documentation!$H$3:$H$19,MATCH($I19,Documentation!$B$3:$B$19,0)),"Done"))))="Done","No","Yes")) -> No | L19: =IF(AND($H19<>"Done",$K19="No"),ROW(),"")
A20: Phase 2 · Provisional v0.1 assets | B20: 2.9 | C20: Draft the Builder subagent definition | D20: assets/agents/builder.md exists and names the claude/ticket-<n>-<slug> branch convention and the baseline-design-only rule | E20: 40 | F20: 3 | G20: =IFERROR(INDEX(Config!$E$5:$E$9,MATCH($F20,Config!$D$5:$D$9,0)),0) -> 11 | H20: Done | I20: 2.1 | J20: §5.4: normal build tickets use frontend-design + design-reference only. | K20: =IF($I20="","No",IF(IFERROR(INDEX(Setup!$H$3:$H$62,MATCH($I20,Setup!$B$3:$B$62,0)),IFERROR(INDEX('App 1'!$H$3:$H$31,MATCH($I20,'App 1'!$B$3:$B$31,0)),IFERROR(INDEX('App 2'!$H$3:$H$11,MATCH($I20,'App 2'!$B$3:$B$11,0)),IFERROR(INDEX(Documentation!$H$3:$H$19,MATCH($I20,Documentation!$B$3:$B$19,0)),"Done"))))="Done","No","Yes")) -> No | L20: =IF(AND($H20<>"Done",$K20="No"),ROW(),"")
A21: Phase 2 · Provisional v0.1 assets | B21: 2.10 | C21: Draft the QA subagent definition with the five-part PR packet | D21: assets/agents/qa.md exists and lists all five packet items in order, preview URL first | E21: 50 | F21: 3 | G21: =IFERROR(INDEX(Config!$E$5:$E$9,MATCH($F21,Config!$D$5:$D$9,0)),0) -> 11 | H21: Done | I21: 2.1 | J21: §4.8. A packet missing an item is a QA-definition bug, not a process failure. | K21: =IF($I21="","No",IF(IFERROR(INDEX(Setup!$H$3:$H$62,MATCH($I21,Setup!$B$3:$B$62,0)),IFERROR(INDEX('App 1'!$H$3:$H$31,MATCH($I21,'App 1'!$B$3:$B$31,0)),IFERROR(INDEX('App 2'!$H$3:$H$11,MATCH($I21,'App 2'!$B$3:$B$11,0)),IFERROR(INDEX(Documentation!$H$3:$H$19,MATCH($I21,Documentation!$B$3:$B$19,0)),"Done"))))="Done","No","Yes")) -> No | L21: =IF(AND($H21<>"Done",$K21="No"),ROW(),"")
A22: Phase 2 · Provisional v0.1 assets | B22: 2.11 | C22: Draft the orchestrator routine prompt | D22: assets/orchestrator-prompt.md exists and contains all four encoded behaviours: cheap-exit, stale-card recovery, Tier-1-blocks-ticket-not-run, inline decisions-log appending | E22: 60 | F22: 4 | G22: =IFERROR(INDEX(Config!$E$5:$E$9,MATCH($F22,Config!$D$5:$D$9,0)),0) -> 17 | H22: Done | I22: 2.10 | J22: Also needs 2.8, 2.9 finished. §12. Check each of the four off by name before marking Done. | K22: =IF($I22="","No",IF(IFERROR(INDEX(Setup!$H$3:$H$62,MATCH($I22,Setup!$B$3:$B$62,0)),IFERROR(INDEX('App 1'!$H$3:$H$31,MATCH($I22,'App 1'!$B$3:$B$31,0)),IFERROR(INDEX('App 2'!$H$3:$H$11,MATCH($I22,'App 2'!$B$3:$B$11,0)),IFERROR(INDEX(Documentation!$H$3:$H$19,MATCH($I22,Documentation!$B$3:$B$19,0)),"Done"))))="Done","No","Yes")) -> No | L22: =IF(AND($H22<>"Done",$K22="No"),ROW(),"")
A23: Phase 2 · Provisional v0.1 assets | B23: 2.12 | C23: Close the timebox and label the assets v0.1 | D23: Every file in /assets carries a 'v0.1 — provisional, revised at Phase 8' header line and the work has stopped | E23: 10 | F23: 1 | G23: =IFERROR(INDEX(Config!$E$5:$E$9,MATCH($F23,Config!$D$5:$D$9,0)),0) -> 4 | H23: Done | I23: 2.11 | J23: One session, timeboxed. Polishing theory here is a quota burn Phase 8 undoes. | K23: =IF($I23="","No",IF(IFERROR(INDEX(Setup!$H$3:$H$62,MATCH($I23,Setup!$B$3:$B$62,0)),IFERROR(INDEX('App 1'!$H$3:$H$31,MATCH($I23,'App 1'!$B$3:$B$31,0)),IFERROR(INDEX('App 2'!$H$3:$H$11,MATCH($I23,'App 2'!$B$3:$B$11,0)),IFERROR(INDEX(Documentation!$H$3:$H$19,MATCH($I23,Documentation!$B$3:$B$19,0)),"Done"))))="Done","No","Yes")) -> No | L23: =IF(AND($H23<>"Done",$K23="No"),ROW(),"")
A24: Phase 3 · Infrastructure setup | B24: 3.1 | C24: Create the GitHub repo for the FPL app | D24: github.com/<you>/fpl-advisor exists and is cloned locally | E24: 15 | F24: 1 | G24: =IFERROR(INDEX(Config!$E$5:$E$9,MATCH($F24,Config!$D$5:$D$9,0)),0) -> 4 | H24: Done | J24: One repo per app (§4.1). | K24: =IF($I24="","No",IF(IFERROR(INDEX(Setup!$H$3:$H$62,MATCH($I24,Setup!$B$3:$B$62,0)),IFERROR(INDEX('App 1'!$H$3:$H$31,MATCH($I24,'App 1'!$B$3:$B$31,0)),IFERROR(INDEX('App 2'!$H$3:$H$11,MATCH($I24,'App 2'!$B$3:$B$11,0)),IFERROR(INDEX(Documentation!$H$3:$H$19,MATCH($I24,Documentation!$B$3:$B$19,0)),"Done"))))="Done","No","Yes")) -> No | L24: =IF(AND($H24<>"Done",$K24="No"),ROW(),"")
A25: Phase 3 · Infrastructure setup | B25: 3.2 | C25: Add README and a CLAUDE.md stub to the app repo | D25: Both files are committed to main and CLAUDE.md names the branch convention claude/ticket-<n>-<slug> | E25: 30 | F25: 2 | G25: =IFERROR(INDEX(Config!$E$5:$E$9,MATCH($F25,Config!$D$5:$D$9,0)),0) -> 7 | H25: Done | I25: 3.1 | J25: Every routine run starts from zero context — CLAUDE.md is how it gets any. | K25: =IF($I25="","No",IF(IFERROR(INDEX(Setup!$H$3:$H$62,MATCH($I25,Setup!$B$3:$B$62,0)),IFERROR(INDEX('App 1'!$H$3:$H$31,MATCH($I25,'App 1'!$B$3:$B$31,0)),IFERROR(INDEX('App 2'!$H$3:$H$11,MATCH($I25,'App 2'!$B$3:$B$11,0)),IFERROR(INDEX(Documentation!$H$3:$H$19,MATCH($I25,Documentation!$B$3:$B$19,0)),"Done"))))="Done","No","Yes")) -> No | L25: =IF(AND($H25<>"Done",$K25="No"),ROW(),"")
A26: Phase 3 · Infrastructure setup | B26: 3.3 | C26: Create decisions.md with its two sections | D26: decisions.md is committed containing the HIGH-IMPACT and ROUTINE headings and one example entry with a 'because' | E26: 15 | F26: 1 | G26: =IFERROR(INDEX(Config!$E$5:$E$9,MATCH($F26,Config!$D$5:$D$9,0)),0) -> 4 | H26: Done | I26: 3.1 | J26: §4.6. The example entry is what teaches the format. | K26: =IF($I26="","No",IF(IFERROR(INDEX(Setup!$H$3:$H$62,MATCH($I26,Setup!$B$3:$B$62,0)),IFERROR(INDEX('App 1'!$H$3:$H$31,MATCH($I26,'App 1'!$B$3:$B$31,0)),IFERROR(INDEX('App 2'!$H$3:$H$11,MATCH($I26,'App 2'!$B$3:$B$11,0)),IFERROR(INDEX(Documentation!$H$3:$H$19,MATCH($I26,Documentation!$B$3:$B$19,0)),"Done"))))="Done","No","Yes")) -> No | L26: =IF(AND($H26<>"Done",$K26="No"),ROW(),"")
A27: Phase 3 · Infrastructure setup | B27: 3.4 | C27: Create the GitHub project board | D27: A project board is linked to the fpl-advisor repo and opens from the repo's Projects tab | E27: 20 | F27: 2 | G27: =IFERROR(INDEX(Config!$E$5:$E$9,MATCH($F27,Config!$D$5:$D$9,0)),0) -> 7 | H27: Done | I27: 3.1 | K27: =IF($I27="","No",IF(IFERROR(INDEX(Setup!$H$3:$H$62,MATCH($I27,Setup!$B$3:$B$62,0)),IFERROR(INDEX('App 1'!$H$3:$H$31,MATCH($I27,'App 1'!$B$3:$B$31,0)),IFERROR(INDEX('App 2'!$H$3:$H$11,MATCH($I27,'App 2'!$B$3:$B$11,0)),IFERROR(INDEX(Documentation!$H$3:$H$19,MATCH($I27,Documentation!$B$3:$B$19,0)),"Done"))))="Done","No","Yes")) -> No | L27: =IF(AND($H27<>"Done",$K27="No"),ROW(),"")
A28: Phase 3 · Infrastructure setup | B28: 3.5 | C28: Configure the five board columns | D28: The board shows exactly: Ready, In progress, For review, Done, Blocked | E28: 20 | F28: 2 | G28: =IFERROR(INDEX(Config!$E$5:$E$9,MATCH($F28,Config!$D$5:$D$9,0)),0) -> 7 | H28: Done | I28: 3.4 | J28: §4.3. Four working columns plus Blocked — do not re-add Building/QA/Review. | K28: =IF($I28="","No",IF(IFERROR(INDEX(Setup!$H$3:$H$62,MATCH($I28,Setup!$B$3:$B$62,0)),IFERROR(INDEX('App 1'!$H$3:$H$31,MATCH($I28,'App 1'!$B$3:$B$31,0)),IFERROR(INDEX('App 2'!$H$3:$H$11,MATCH($I28,'App 2'!$B$3:$B$11,0)),IFERROR(INDEX(Documentation!$H$3:$H$19,MATCH($I28,Documentation!$B$3:$B$19,0)),"Done"))))="Done","No","Yes")) -> No | L28: =IF(AND($H28<>"Done",$K28="No"),ROW(),"")
A29: Phase 3 · Infrastructure setup | B29: 3.6 | C29: Turn the ticket template into a GitHub issue template | D29: .github/ISSUE_TEMPLATE/ticket.md is committed and appears in the 'New issue' picker | E29: 30 | F29: 2 | G29: =IFERROR(INDEX(Config!$E$5:$E$9,MATCH($F29,Config!$D$5:$D$9,0)),0) -> 7 | H29: Done | I29: 3.1 | J29: Also needs 2.6 finished. | K29: =IF($I29="","No",IF(IFERROR(INDEX(Setup!$H$3:$H$62,MATCH($I29,Setup!$B$3:$B$62,0)),IFERROR(INDEX('App 1'!$H$3:$H$31,MATCH($I29,'App 1'!$B$3:$B$31,0)),IFERROR(INDEX('App 2'!$H$3:$H$11,MATCH($I29,'App 2'!$B$3:$B$11,0)),IFERROR(INDEX(Documentation!$H$3:$H$19,MATCH($I29,Documentation!$B$3:$B$19,0)),"Done"))))="Done","No","Yes")) -> No | L29: =IF(AND($H29<>"Done",$K29="No"),ROW(),"")
A30: Phase 3 · Infrastructure setup | B30: 3.7 | C30: Scaffold the PWA | D30: The repo builds locally and serves a page with a valid manifest.json and registered service worker | E30: 60 | F30: 3 | G30: =IFERROR(INDEX(Config!$E$5:$E$9,MATCH($F30,Config!$D$5:$D$9,0)),0) -> 11 | H30: Done | I30: 3.1 | J30: §4.1: one codebase, iPhone home screen + laptop browser. No App Store. | K30: =IF($I30="","No",IF(IFERROR(INDEX(Setup!$H$3:$H$62,MATCH($I30,Setup!$B$3:$B$62,0)),IFERROR(INDEX('App 1'!$H$3:$H$31,MATCH($I30,'App 1'!$B$3:$B$31,0)),IFERROR(INDEX('App 2'!$H$3:$H$11,MATCH($I30,'App 2'!$B$3:$B$11,0)),IFERROR(INDEX(Documentation!$H$3:$H$19,MATCH($I30,Documentation!$B$3:$B$19,0)),"Done"))))="Done","No","Yes")) -> No | L30: =IF(AND($H30<>"Done",$K30="No"),ROW(),"")
A31: Phase 3 · Infrastructure setup | B31: 3.8 | C31: Install the scaffolded PWA to the iPhone home screen | D31: The app icon is on the iPhone home screen and opens without Safari chrome | E31: 30 | F31: 3 | G31: =IFERROR(INDEX(Config!$E$5:$E$9,MATCH($F31,Config!$D$5:$D$9,0)),0) -> 11 | H31: Done | I31: 3.7 | J31: Do this now, not after app #1 — an install failure found late is expensive. | K31: =IF($I31="","No",IF(IFERROR(INDEX(Setup!$H$3:$H$62,MATCH($I31,Setup!$B$3:$B$62,0)),IFERROR(INDEX('App 1'!$H$3:$H$31,MATCH($I31,'App 1'!$B$3:$B$31,0)),IFERROR(INDEX('App 2'!$H$3:$H$11,MATCH($I31,'App 2'!$B$3:$B$11,0)),IFERROR(INDEX(Documentation!$H$3:$H$19,MATCH($I31,Documentation!$B$3:$B$19,0)),"Done"))))="Done","No","Yes")) -> No | L31: =IF(AND($H31<>"Done",$K31="No"),ROW(),"")
A32: Phase 3 · Infrastructure setup | B32: 3.9 | C32: Connect the repo to Vercel and deploy | D32: The Vercel production URL loads the scaffolded app | E32: 30 | F32: 2 | G32: =IFERROR(INDEX(Config!$E$5:$E$9,MATCH($F32,Config!$D$5:$D$9,0)),0) -> 7 | H32: Done | I32: 3.7 | J32: Creating the Vercel account is an owner-only action (Tier 1). | K32: =IF($I32="","No",IF(IFERROR(INDEX(Setup!$H$3:$H$62,MATCH($I32,Setup!$B$3:$B$62,0)),IFERROR(INDEX('App 1'!$H$3:$H$31,MATCH($I32,'App 1'!$B$3:$B$31,0)),IFERROR(INDEX('App 2'!$H$3:$H$11,MATCH($I32,'App 2'!$B$3:$B$11,0)),IFERROR(INDEX(Documentation!$H$3:$H$19,MATCH($I32,Documentation!$B$3:$B$19,0)),"Done"))))="Done","No","Yes")) -> No | L32: =IF(AND($H32<>"Done",$K32="No"),ROW(),"")
A33: Phase 3 · Infrastructure setup | B33: 3.10 | C33: Verify a PR preview URL is generated | D33: A throwaway PR has been opened and its Vercel preview URL loads the changed page on the phone | E33: 30 | F33: 3 | G33: =IFERROR(INDEX(Config!$E$5:$E$9,MATCH($F33,Config!$D$5:$D$9,0)),0) -> 11 | H33: Done | I33: 3.9 | J33: §4.8: the preview URL is load-bearing for phone review. Prove it works. | K33: =IF($I33="","No",IF(IFERROR(INDEX(Setup!$H$3:$H$62,MATCH($I33,Setup!$B$3:$B$62,0)),IFERROR(INDEX('App 1'!$H$3:$H$31,MATCH($I33,'App 1'!$B$3:$B$31,0)),IFERROR(INDEX('App 2'!$H$3:$H$11,MATCH($I33,'App 2'!$B$3:$B$11,0)),IFERROR(INDEX(Documentation!$H$3:$H$19,MATCH($I33,Documentation!$B$3:$B$19,0)),"Done"))))="Done","No","Yes")) -> No | L33: =IF(AND($H33<>"Done",$K33="No"),ROW(),"")
A34: Phase 3 · Infrastructure setup | B34: 3.11 | C34: Create the Supabase project | D34: A Supabase project exists and its dashboard shows the project URL and anon key | E34: 30 | F34: 2 | G34: =IFERROR(INDEX(Config!$E$5:$E$9,MATCH($F34,Config!$D$5:$D$9,0)),0) -> 7 | H34: Done | J34: Owner-only account creation. Agents never do this. | K34: =IF($I34="","No",IF(IFERROR(INDEX(Setup!$H$3:$H$62,MATCH($I34,Setup!$B$3:$B$62,0)),IFERROR(INDEX('App 1'!$H$3:$H$31,MATCH($I34,'App 1'!$B$3:$B$31,0)),IFERROR(INDEX('App 2'!$H$3:$H$11,MATCH($I34,'App 2'!$B$3:$B$11,0)),IFERROR(INDEX(Documentation!$H$3:$H$19,MATCH($I34,Documentation!$B$3:$B$19,0)),"Done"))))="Done","No","Yes")) -> No | L34: =IF(AND($H34<>"Done",$K34="No"),ROW(),"")
A35: Phase 3 · Infrastructure setup | B35: 3.12 | C35: Put the Supabase keys into Vercel environment variables | D35: A deployed preview successfully reads from Supabase without any key committed to the repo | E35: 30 | F35: 3 | G35: =IFERROR(INDEX(Config!$E$5:$E$9,MATCH($F35,Config!$D$5:$D$9,0)),0) -> 11 | H35: Done | I35: 3.11 | J35: Also needs 3.10 finished. §7: static-only hosting has nowhere to hide keys — this is why Vercel. | K35: =IF($I35="","No",IF(IFERROR(INDEX(Setup!$H$3:$H$62,MATCH($I35,Setup!$B$3:$B$62,0)),IFERROR(INDEX('App 1'!$H$3:$H$31,MATCH($I35,'App 1'!$B$3:$B$31,0)),IFERROR(INDEX('App 2'!$H$3:$H$11,MATCH($I35,'App 2'!$B$3:$B$11,0)),IFERROR(INDEX(Documentation!$H$3:$H$19,MATCH($I35,Documentation!$B$3:$B$19,0)),"Done"))))="Done","No","Yes")) -> No | L35: =IF(AND($H35<>"Done",$K35="No"),ROW(),"")
A36: Phase 3 · Infrastructure setup | B36: 3.13 | C36: Read the Impeccable SKILL.md before installing | D36: The SKILL.md text has been read end to end and anything surprising is noted in decisions.md | E36: 30 | F36: 2 | G36: =IFERROR(INDEX(Config!$E$5:$E$9,MATCH($F36,Config!$D$5:$D$9,0)),0) -> 7 | H36: Done | J36: §5.5. These are prompt files that enter the agent's working context. | K36: =IF($I36="","No",IF(IFERROR(INDEX(Setup!$H$3:$H$62,MATCH($I36,Setup!$B$3:$B$62,0)),IFERROR(INDEX('App 1'!$H$3:$H$31,MATCH($I36,'App 1'!$B$3:$B$31,0)),IFERROR(INDEX('App 2'!$H$3:$H$11,MATCH($I36,'App 2'!$B$3:$B$11,0)),IFERROR(INDEX(Documentation!$H$3:$H$19,MATCH($I36,Documentation!$B$3:$B$19,0)),"Done"))))="Done","No","Yes")) -> No | L36: =IF(AND($H36<>"Done",$K36="No"),ROW(),"")
A37: Phase 3 · Infrastructure setup | B37: 3.14 | C37: Install Impeccable and run /impeccable init | D37: PRODUCT.md and DESIGN.md exist in the app repo, generated by init | E37: 45 | F37: 3 | G37: =IFERROR(INDEX(Config!$E$5:$E$9,MATCH($F37,Config!$D$5:$D$9,0)),0) -> 11 | H37: Done | I37: 3.13 | J37: Also needs 3.7 finished. §5.2. Primary design layer. Do not also install a Taste Skill variant. | K37: =IF($I37="","No",IF(IFERROR(INDEX(Setup!$H$3:$H$62,MATCH($I37,Setup!$B$3:$B$62,0)),IFERROR(INDEX('App 1'!$H$3:$H$31,MATCH($I37,'App 1'!$B$3:$B$31,0)),IFERROR(INDEX('App 2'!$H$3:$H$11,MATCH($I37,'App 2'!$B$3:$B$11,0)),IFERROR(INDEX(Documentation!$H$3:$H$19,MATCH($I37,Documentation!$B$3:$B$19,0)),"Done"))))="Done","No","Yes")) -> No | L37: =IF(AND($H37<>"Done",$K37="No"),ROW(),"")
A38: Phase 3 · Infrastructure setup | B38: 3.15 | C38: Read and install emil-design-eng from the official repo | D38: The skill is installed from github.com/emilkowalski/skills and appears in the installed skills list | E38: 30 | F38: 2 | G38: =IFERROR(INDEX(Config!$E$5:$E$9,MATCH($F38,Config!$D$5:$D$9,0)),0) -> 7 | H38: Done | J38: §5.1: beware third-party imitations under similar names. | K38: =IF($I38="","No",IF(IFERROR(INDEX(Setup!$H$3:$H$62,MATCH($I38,Setup!$B$3:$B$62,0)),IFERROR(INDEX('App 1'!$H$3:$H$31,MATCH($I38,'App 1'!$B$3:$B$31,0)),IFERROR(INDEX('App 2'!$H$3:$H$11,MATCH($I38,'App 2'!$B$3:$B$11,0)),IFERROR(INDEX(Documentation!$H$3:$H$19,MATCH($I38,Documentation!$B$3:$B$19,0)),"Done"))))="Done","No","Yes")) -> No | L38: =IF(AND($H38<>"Done",$K38="No"),ROW(),"")
A39: Phase 3 · Infrastructure setup | B39: 3.16 | C39: Verify the installed design skill set | D39: The skills list shows exactly frontend-design, Impeccable and emil-design-eng — no Taste Skill variant | E39: 20 | F39: 2 | G39: =IFERROR(INDEX(Config!$E$5:$E$9,MATCH($F39,Config!$D$5:$D$9,0)),0) -> 7 | H39: Done | I39: 3.15 | J39: Also needs 3.14 finished. §5.2: swap, never stack. | K39: =IF($I39="","No",IF(IFERROR(INDEX(Setup!$H$3:$H$62,MATCH($I39,Setup!$B$3:$B$62,0)),IFERROR(INDEX('App 1'!$H$3:$H$31,MATCH($I39,'App 1'!$B$3:$B$31,0)),IFERROR(INDEX('App 2'!$H$3:$H$11,MATCH($I39,'App 2'!$B$3:$B$11,0)),IFERROR(INDEX(Documentation!$H$3:$H$19,MATCH($I39,Documentation!$B$3:$B$19,0)),"Done"))))="Done","No","Yes")) -> No | L39: =IF(AND($H39<>"Done",$K39="No"),ROW(),"")
A40: Phase 4 · Agent & skill definitions | B40: 4.1 | C40: Create the .claude/agents directory in the app repo | D40: The directory exists on main and is visible on GitHub | E40: 10 | F40: 1 | G40: =IFERROR(INDEX(Config!$E$5:$E$9,MATCH($F40,Config!$D$5:$D$9,0)),0) -> 4 | H40: Done | I40: 3.2 | K40: =IF($I40="","No",IF(IFERROR(INDEX(Setup!$H$3:$H$62,MATCH($I40,Setup!$B$3:$B$62,0)),IFERROR(INDEX('App 1'!$H$3:$H$31,MATCH($I40,'App 1'!$B$3:$B$31,0)),IFERROR(INDEX('App 2'!$H$3:$H$11,MATCH($I40,'App 2'!$B$3:$B$11,0)),IFERROR(INDEX(Documentation!$H$3:$H$19,MATCH($I40,Documentation!$B$3:$B$19,0)),"Done"))))="Done","No","Yes")) -> No | L40: =IF(AND($H40<>"Done",$K40="No"),ROW(),"")
...

Sheet App 1
A1: APP 1 | C1: Build FPL through the pipeline, then rewrite the assets from what actually happened.
A2: Phase | B2: Task ID | C2: Task | D2: What "done" looks like | E2: Est. time (mins) | F2: Difficulty (1-5) | G2: XP | H2: Status | I2: Blocked by | J2: Notes | K2: Blocked? (auto) | L2: Queue rank (auto)
A3: Phase 7 · Build app #1 (FPL) | B3: 7.1 | C3: Write the FPL product brief from the template | D3: product-brief.md is committed to fpl-advisor with every template section filled, including the Tier-3 currency declaration | E3: 75 | F3: 3 | G3: =IFERROR(INDEX(Config!$E$5:$E$9,MATCH($F3,Config!$D$5:$D$9,0)),0) -> 11 | H3: Not started | I3: 6.10 | J3: Also needs 2.5 finished. The Analyst holds this. Spec quality is the real bottleneck (risk #3). | K3: =IF($I3="","No",IF(IFERROR(INDEX(Setup!$H$3:$H$62,MATCH($I3,Setup!$B$3:$B$62,0)),IFERROR(INDEX('App 1'!$H$3:$H$31,MATCH($I3,'App 1'!$B$3:$B$31,0)),IFERROR(INDEX('App 2'!$H$3:$H$11,MATCH($I3,'App 2'!$B$3:$B$11,0)),IFERROR(INDEX(Documentation!$H$3:$H$19,MATCH($I3,Documentation!$B$3:$B$19,0)),"Done"))))="Done","No","Yes")) -> Yes | L3: =IF(AND($H3<>"Done",$K3="No"),ROW(),"")
A4: Phase 7 · Build app #1 (FPL) | B4: 7.2 | C4: Choose the FPL data source and document the graceful failure path | D4: The brief names one data source with a written 'because', and states what the app shows when the feed breaks | E4: 60 | F4: 4 | G4: =IFERROR(INDEX(Config!$E$5:$E$9,MATCH($F4,Config!$D$5:$D$9,0)),0) -> 17 | H4: Not started | I4: 7.1 | J4: §3 notes 1-2. Unofficial, undocumented API — expect breakage. | K4: =IF($I4="","No",IF(IFERROR(INDEX(Setup!$H$3:$H$62,MATCH($I4,Setup!$B$3:$B$62,0)),IFERROR(INDEX('App 1'!$H$3:$H$31,MATCH($I4,'App 1'!$B$3:$B$31,0)),IFERROR(INDEX('App 2'!$H$3:$H$11,MATCH($I4,'App 2'!$B$3:$B$11,0)),IFERROR(INDEX(Documentation!$H$3:$H$19,MATCH($I4,Documentation!$B$3:$B$19,0)),"Done"))))="Done","No","Yes")) -> Yes | L4: =IF(AND($H4<>"Done",$K4="No"),ROW(),"")
A5: Phase 7 · Build app #1 (FPL) | B5: 7.3 | C5: Draft the FPL v1 ticket backlog | D5: 8-12 issues exist using the ticket template, each with a definition-of-done, ordered in Ready | E5: 80 | F5: 3 | G5: =IFERROR(INDEX(Config!$E$5:$E$9,MATCH($F5,Config!$D$5:$D$9,0)),0) -> 11 | H5: Not started | I5: 7.1 | J5: Order so a usable thing exists early. | K5: =IF($I5="","No",IF(IFERROR(INDEX(Setup!$H$3:$H$62,MATCH($I5,Setup!$B$3:$B$62,0)),IFERROR(INDEX('App 1'!$H$3:$H$31,MATCH($I5,'App 1'!$B$3:$B$31,0)),IFERROR(INDEX('App 2'!$H$3:$H$11,MATCH($I5,'App 2'!$B$3:$B$11,0)),IFERROR(INDEX(Documentation!$H$3:$H$19,MATCH($I5,Documentation!$B$3:$B$19,0)),"Done"))))="Done","No","Yes")) -> Yes | L5: =IF(AND($H5<>"Done",$K5="No"),ROW(),"")
A6: Phase 7 · Build app #1 (FPL) | B6: 7.4 | C6: Lint ticket batch 1 | D6: The first two tickets have been through an Analyst lint pass, including the Tier-1 scope check, and edited | E6: 40 | F6: 2 | G6: =IFERROR(INDEX(Config!$E$5:$E$9,MATCH($F6,Config!$D$5:$D$9,0)),0) -> 7 | H6: Not started | I6: 7.3 | J6: §4.5 Rule A: the lint pass checks scope, not just wording. | K6: =IF($I6="","No",IF(IFERROR(INDEX(Setup!$H$3:$H$62,MATCH($I6,Setup!$B$3:$B$62,0)),IFERROR(INDEX('App 1'!$H$3:$H$31,MATCH($I6,'App 1'!$B$3:$B$31,0)),IFERROR(INDEX('App 2'!$H$3:$H$11,MATCH($I6,'App 2'!$B$3:$B$11,0)),IFERROR(INDEX(Documentation!$H$3:$H$19,MATCH($I6,Documentation!$B$3:$B$19,0)),"Done"))))="Done","No","Yes")) -> Yes | L6: =IF(AND($H6<>"Done",$K6="No"),ROW(),"")
A7: Phase 7 · Build app #1 (FPL) | B7: 7.5 | C7: Queue batch 1 and confirm Ready order | D7: The two linted tickets sit at the top of Ready in the intended order | E7: 10 | F7: 1 | G7: =IFERROR(INDEX(Config!$E$5:$E$9,MATCH($F7,Config!$D$5:$D$9,0)),0) -> 4 | H7: Not started | I7: 7.4 | J7: §6: 2 tickets per run. | K7: =IF($I7="","No",IF(IFERROR(INDEX(Setup!$H$3:$H$62,MATCH($I7,Setup!$B$3:$B$62,0)),IFERROR(INDEX('App 1'!$H$3:$H$31,MATCH($I7,'App 1'!$B$3:$B$31,0)),IFERROR(INDEX('App 2'!$H$3:$H$11,MATCH($I7,'App 2'!$B$3:$B$11,0)),IFERROR(INDEX(Documentation!$H$3:$H$19,MATCH($I7,Documentation!$B$3:$B$19,0)),"Done"))))="Done","No","Yes")) -> Yes | L7: =IF(AND($H7<>"Done",$K7="No"),ROW(),"")
A8: Phase 7 · Build app #1 (FPL) | B8: 7.6 | C8: Morning review, run 1 | D8: Each PR from run 1 has been opened on the phone, the preview tapped and the feature used, then merged or bounced with a written sentence | E8: 25 | F8: 2 | G8: =IFERROR(INDEX(Config!$E$5:$E$9,MATCH($F8,Config!$D$5:$D$9,0)),0) -> 7 | H8: Not started | I8: 7.5 | J8: Target 10-15 minutes. If you can't say what you merged, the gate has failed (risk #7). | K8: =IF($I8="","No",IF(IFERROR(INDEX(Setup!$H$3:$H$62,MATCH($I8,Setup!$B$3:$B$62,0)),IFERROR(INDEX('App 1'!$H$3:$H$31,MATCH($I8,'App 1'!$B$3:$B$31,0)),IFERROR(INDEX('App 2'!$H$3:$H$11,MATCH($I8,'App 2'!$B$3:$B$11,0)),IFERROR(INDEX(Documentation!$H$3:$H$19,MATCH($I8,Documentation!$B$3:$B$19,0)),"Done"))))="Done","No","Yes")) -> Yes | L8: =IF(AND($H8<>"Done",$K8="No"),ROW(),"")
A9: Phase 7 · Build app #1 (FPL) | B9: 7.7 | C9: Morning review, run 2 | D9: Same as run 1: previews used, PRs merged or bounced with a written sentence | E9: 25 | F9: 2 | G9: =IFERROR(INDEX(Config!$E$5:$E$9,MATCH($F9,Config!$D$5:$D$9,0)),0) -> 7 | H9: Not started | I9: 7.6 | K9: =IF($I9="","No",IF(IFERROR(INDEX(Setup!$H$3:$H$62,MATCH($I9,Setup!$B$3:$B$62,0)),IFERROR(INDEX('App 1'!$H$3:$H$31,MATCH($I9,'App 1'!$B$3:$B$31,0)),IFERROR(INDEX('App 2'!$H$3:$H$11,MATCH($I9,'App 2'!$B$3:$B$11,0)),IFERROR(INDEX(Documentation!$H$3:$H$19,MATCH($I9,Documentation!$B$3:$B$19,0)),"Done"))))="Done","No","Yes")) -> Yes | L9: =IF(AND($H9<>"Done",$K9="No"),ROW(),"")
A10: Phase 7 · Build app #1 (FPL) | B10: 7.8 | C10: Morning review, run 3 | D10: Same as run 1: previews used, PRs merged or bounced with a written sentence | E10: 25 | F10: 2 | G10: =IFERROR(INDEX(Config!$E$5:$E$9,MATCH($F10,Config!$D$5:$D$9,0)),0) -> 7 | H10: Not started | I10: 7.7 | K10: =IF($I10="","No",IF(IFERROR(INDEX(Setup!$H$3:$H$62,MATCH($I10,Setup!$B$3:$B$62,0)),IFERROR(INDEX('App 1'!$H$3:$H$31,MATCH($I10,'App 1'!$B$3:$B$31,0)),IFERROR(INDEX('App 2'!$H$3:$H$11,MATCH($I10,'App 2'!$B$3:$B$11,0)),IFERROR(INDEX(Documentation!$H$3:$H$19,MATCH($I10,Documentation!$B$3:$B$19,0)),"Done"))))="Done","No","Yes")) -> Yes | L10: =IF(AND($H10<>"Done",$K10="No"),ROW(),"")
A11: Phase 7 · Build app #1 (FPL) | B11: 7.9 | C11: Handle the first real Blocked card | D11: The Tier-1 question on the card has been answered in a comment and the card returned to Ready | E11: 20 | F11: 2 | G11: =IFERROR(INDEX(Config!$E$5:$E$9,MATCH($F11,Config!$D$5:$D$9,0)),0) -> 7 | H11: Not started | I11: 7.6 | J11: Answerable from the phone. If it isn't, the question was written wrong. | K11: =IF($I11="","No",IF(IFERROR(INDEX(Setup!$H$3:$H$62,MATCH($I11,Setup!$B$3:$B$62,0)),IFERROR(INDEX('App 1'!$H$3:$H$31,MATCH($I11,'App 1'!$B$3:$B$31,0)),IFERROR(INDEX('App 2'!$H$3:$H$11,MATCH($I11,'App 2'!$B$3:$B$11,0)),IFERROR(INDEX(Documentation!$H$3:$H$19,MATCH($I11,Documentation!$B$3:$B$19,0)),"Done"))))="Done","No","Yes")) -> Yes | L11: =IF(AND($H11<>"Done",$K11="No"),ROW(),"")
A12: Phase 7 · Build app #1 (FPL) | B12: 7.10 | C12: Handle the first revision-cap failure | D12: A ticket that hit the 2-revision cap has been re-specced or split, and the reason is written in decisions.md | E12: 45 | F12: 3 | G12: =IFERROR(INDEX(Config!$E$5:$E$9,MATCH($F12,Config!$D$5:$D$9,0)),0) -> 11 | H12: Not started | I12: 7.7 | J12: Cap failures are usually spec failures, not model failures. | K12: =IF($I12="","No",IF(IFERROR(INDEX(Setup!$H$3:$H$62,MATCH($I12,Setup!$B$3:$B$62,0)),IFERROR(INDEX('App 1'!$H$3:$H$31,MATCH($I12,'App 1'!$B$3:$B$31,0)),IFERROR(INDEX('App 2'!$H$3:$H$11,MATCH($I12,'App 2'!$B$3:$B$11,0)),IFERROR(INDEX(Documentation!$H$3:$H$19,MATCH($I12,Documentation!$B$3:$B$19,0)),"Done"))))="Done","No","Yes")) -> Yes | L12: =IF(AND($H12<>"Done",$K12="No"),ROW(),"")
A13: Phase 7 · Build app #1 (FPL) | B13: 7.11 | C13: Handle the first stale-card recovery | D13: A card stranded by a dead run has been resolved per §4.4 2a, and the partial branch either resumed, restarted or deleted | E13: 40 | F13: 3 | G13: =IFERROR(INDEX(Config!$E$5:$E$9,MATCH($F13,Config!$D$5:$D$9,0)),0) -> 11 | H13: Not started | I13: 7.7 | J13: If this never happens, mark Done and note 'not observed'. | K13: =IF($I13="","No",IF(IFERROR(INDEX(Setup!$H$3:$H$62,MATCH($I13,Setup!$B$3:$B$62,0)),IFERROR(INDEX('App 1'!$H$3:$H$31,MATCH($I13,'App 1'!$B$3:$B$31,0)),IFERROR(INDEX('App 2'!$H$3:$H$11,MATCH($I13,'App 2'!$B$3:$B$11,0)),IFERROR(INDEX(Documentation!$H$3:$H$19,MATCH($I13,Documentation!$B$3:$B$19,0)),"Done"))))="Done","No","Yes")) -> Yes | L13: =IF(AND($H13<>"Done",$K13="No"),ROW(),"")
A14: Phase 7 · Build app #1 (FPL) | B14: 7.12 | C14: Lint and queue ticket batch 2 | D14: The next two tickets are linted and queued in Ready | E14: 40 | F14: 2 | G14: =IFERROR(INDEX(Config!$E$5:$E$9,MATCH($F14,Config!$D$5:$D$9,0)),0) -> 7 | H14: Not started | I14: 7.8 | K14: =IF($I14="","No",IF(IFERROR(INDEX(Setup!$H$3:$H$62,MATCH($I14,Setup!$B$3:$B$62,0)),IFERROR(INDEX('App 1'!$H$3:$H$31,MATCH($I14,'App 1'!$B$3:$B$31,0)),IFERROR(INDEX('App 2'!$H$3:$H$11,MATCH($I14,'App 2'!$B$3:$B$11,0)),IFERROR(INDEX(Documentation!$H$3:$H$19,MATCH($I14,Documentation!$B$3:$B$19,0)),"Done"))))="Done","No","Yes")) -> Yes | L14: =IF(AND($H14<>"Done",$K14="No"),ROW(),"")
A15: Phase 7 · Build app #1 (FPL) | B15: 7.13 | C15: Run a polish ticket using Impeccable | D15: A polish-type ticket has shipped a PR whose packet names which Impeccable detector rules fired | E15: 45 | F15: 3 | G15: =IFERROR(INDEX(Config!$E$5:$E$9,MATCH($F15,Config!$D$5:$D$9,0)),0) -> 11 | H15: Not started | I15: 7.12 | J15: §5.4. Heavy design skills only inside polish tickets. | K15: =IF($I15="","No",IF(IFERROR(INDEX(Setup!$H$3:$H$62,MATCH($I15,Setup!$B$3:$B$62,0)),IFERROR(INDEX('App 1'!$H$3:$H$31,MATCH($I15,'App 1'!$B$3:$B$31,0)),IFERROR(INDEX('App 2'!$H$3:$H$11,MATCH($I15,'App 2'!$B$3:$B$11,0)),IFERROR(INDEX(Documentation!$H$3:$H$19,MATCH($I15,Documentation!$B$3:$B$19,0)),"Done"))))="Done","No","Yes")) -> Yes | L15: =IF(AND($H15<>"Done",$K15="No"),ROW(),"")
A16: Phase 7 · Build app #1 (FPL) | B16: 7.14 | C16: Run a motion polish ticket using emil-design-eng | D16: A second polish ticket has shipped with at least one animation added and a stated reason for the curve chosen | E16: 40 | F16: 3 | G16: =IFERROR(INDEX(Config!$E$5:$E$9,MATCH($F16,Config!$D$5:$D$9,0)),0) -> 11 | H16: Not started | I16: 7.13 | J16: Motion pass comes after a UI exists, not alongside it. | K16: =IF($I16="","No",IF(IFERROR(INDEX(Setup!$H$3:$H$62,MATCH($I16,Setup!$B$3:$B$62,0)),IFERROR(INDEX('App 1'!$H$3:$H$31,MATCH($I16,'App 1'!$B$3:$B$31,0)),IFERROR(INDEX('App 2'!$H$3:$H$11,MATCH($I16,'App 2'!$B$3:$B$11,0)),IFERROR(INDEX(Documentation!$H$3:$H$19,MATCH($I16,Documentation!$B$3:$B$19,0)),"Done"))))="Done","No","Yes")) -> Yes | L16: =IF(AND($H16<>"Done",$K16="No"),ROW(),"")
A17: Phase 7 · Build app #1 (FPL) | B17: 7.15 | C17: Do the weekly quota check | D17: A line in environment-baseline.md records, for each week, whether any usage limit was hit | E17: 25 | F17: 2 | G17: =IFERROR(INDEX(Config!$E$5:$E$9,MATCH($F17,Config!$D$5:$D$9,0)),0) -> 7 | H17: Not started | I17: 7.8 | J17: §11: nightly cadence unlocks after two weeks with no collisions. | K17: =IF($I17="","No",IF(IFERROR(INDEX(Setup!$H$3:$H$62,MATCH($I17,Setup!$B$3:$B$62,0)),IFERROR(INDEX('App 1'!$H$3:$H$31,MATCH($I17,'App 1'!$B$3:$B$31,0)),IFERROR(INDEX('App 2'!$H$3:$H$11,MATCH($I17,'App 2'!$B$3:$B$11,0)),IFERROR(INDEX(Documentation!$H$3:$H$19,MATCH($I17,Documentation!$B$3:$B$19,0)),"Done"))))="Done","No","Yes")) -> Yes | L17: =IF(AND($H17<>"Done",$K17="No"),ROW(),"")
A18: Phase 7 · Build app #1 (FPL) | B18: 7.16 | C18: Audit decisions.md against the health signal | D18: The high-impact entries per run night have been counted and compared against the ~5 threshold, with the count written down | E18: 30 | F18: 2 | G18: =IFERROR(INDEX(Config!$E$5:$E$9,MATCH($F18,Config!$D$5:$D$9,0)),0) -> 7 | H18: Not started | I18: 7.8 | J18: §4.6: regularly over ~5 means the Analyst has gone loose. | K18: =IF($I18="","No",IF(IFERROR(INDEX(Setup!$H$3:$H$62,MATCH($I18,Setup!$B$3:$B$62,0)),IFERROR(INDEX('App 1'!$H$3:$H$31,MATCH($I18,'App 1'!$B$3:$B$31,0)),IFERROR(INDEX('App 2'!$H$3:$H$11,MATCH($I18,'App 2'!$B$3:$B$11,0)),IFERROR(INDEX(Documentation!$H$3:$H$19,MATCH($I18,Documentation!$B$3:$B$19,0)),"Done"))))="Done","No","Yes")) -> Yes | L18: =IF(AND($H18<>"Done",$K18="No"),ROW(),"")
A19: Phase 7 · Build app #1 (FPL) | B19: 7.17 | C19: Install the FPL app and use it for a full gameweek | D19: The PWA is on the iPhone home screen and has been opened on at least three separate days | E19: 30 | F19: 2 | G19: =IFERROR(INDEX(Config!$E$5:$E$9,MATCH($F19,Config!$D$5:$D$9,0)),0) -> 7 | H19: Not started | I19: 7.8 | J19: Using it is how you find what the tickets missed. | K19: =IF($I19="","No",IF(IFERROR(INDEX(Setup!$H$3:$H$62,MATCH($I19,Setup!$B$3:$B$62,0)),IFERROR(INDEX('App 1'!$H$3:$H$31,MATCH($I19,'App 1'!$B$3:$B$31,0)),IFERROR(INDEX('App 2'!$H$3:$H$11,MATCH($I19,'App 2'!$B$3:$B$11,0)),IFERROR(INDEX(Documentation!$H$3:$H$19,MATCH($I19,Documentation!$B$3:$B$19,0)),"Done"))))="Done","No","Yes")) -> Yes | L19: =IF(AND($H19<>"Done",$K19="No"),ROW(),"")
A20: Phase 7 · Build app #1 (FPL) | B20: 7.18 | C20: Declare app #1 Done-mostly | D20: The Ready column is empty of v1 tickets and a written note says what was consciously left out | E20: 20 | F20: 2 | G20: =IFERROR(INDEX(Config!$E$5:$E$9,MATCH($F20,Config!$D$5:$D$9,0)),0) -> 7 | H20: Not started | I20: 7.17 | J20: §11: this is the trigger for a second app in flight. | K20: =IF($I20="","No",IF(IFERROR(INDEX(Setup!$H$3:$H$62,MATCH($I20,Setup!$B$3:$B$62,0)),IFERROR(INDEX('App 1'!$H$3:$H$31,MATCH($I20,'App 1'!$B$3:$B$31,0)),IFERROR(INDEX('App 2'!$H$3:$H$11,MATCH($I20,'App 2'!$B$3:$B$11,0)),IFERROR(INDEX(Documentation!$H$3:$H$19,MATCH($I20,Documentation!$B$3:$B$19,0)),"Done"))))="Done","No","Yes")) -> Yes | L20: =IF(AND($H20<>"Done",$K20="No"),ROW(),"")
A21: Phase 8 · Retrospective & asset revision | B21: 8.1 | C21: Read every session log from app #1 and list the failures | D21: A retro-notes file lists every run, its outcome, and the cause of each failure | E21: 75 | F21: 3 | G21: =IFERROR(INDEX(Config!$E$5:$E$9,MATCH($F21,Config!$D$5:$D$9,0)),0) -> 11 | H21: Not started | I21: 7.18 | J21: Phase 8 is the point of the whole sequence. | K21: =IF($I21="","No",IF(IFERROR(INDEX(Setup!$H$3:$H$62,MATCH($I21,Setup!$B$3:$B$62,0)),IFERROR(INDEX('App 1'!$H$3:$H$31,MATCH($I21,'App 1'!$B$3:$B$31,0)),IFERROR(INDEX('App 2'!$H$3:$H$11,MATCH($I21,'App 2'!$B$3:$B$11,0)),IFERROR(INDEX(Documentation!$H$3:$H$19,MATCH($I21,Documentation!$B$3:$B$19,0)),"Done"))))="Done","No","Yes")) -> Yes | L21: =IF(AND($H21<>"Done",$K21="No"),ROW(),"")
A22: Phase 8 · Retrospective & asset revision | B22: 8.2 | C22: Write the retro: what the v0.1 assets got wrong | D22: The retro notes name, per asset, at least one concrete thing it got wrong and the evidence for it | E22: 60 | F22: 3 | G22: =IFERROR(INDEX(Config!$E$5:$E$9,MATCH($F22,Config!$D$5:$D$9,0)),0) -> 11 | H22: Not started | I22: 8.1 | J22: 'Nothing was wrong' means you didn't look hard enough. | K22: =IF($I22="","No",IF(IFERROR(INDEX(Setup!$H$3:$H$62,MATCH($I22,Setup!$B$3:$B$62,0)),IFERROR(INDEX('App 1'!$H$3:$H$31,MATCH($I22,'App 1'!$B$3:$B$31,0)),IFERROR(INDEX('App 2'!$H$3:$H$11,MATCH($I22,'App 2'!$B$3:$B$11,0)),IFERROR(INDEX(Documentation!$H$3:$H$19,MATCH($I22,Documentation!$B$3:$B$19,0)),"Done"))))="Done","No","Yes")) -> Yes | L22: =IF(AND($H22<>"Done",$K22="No"),ROW(),"")
A23: Phase 8 · Retrospective & asset revision | B23: 8.3 | C23: Revise the product brief template to v1.0 | D23: assets/product-brief-template.md is committed with a v1.0 header and a changelog of what changed and why | E23: 50 | F23: 3 | G23: =IFERROR(INDEX(Config!$E$5:$E$9,MATCH($F23,Config!$D$5:$D$9,0)),0) -> 11 | H23: Not started | I23: 8.2 | K23: =IF($I23="","No",IF(IFERROR(INDEX(Setup!$H$3:$H$62,MATCH($I23,Setup!$B$3:$B$62,0)),IFERROR(INDEX('App 1'!$H$3:$H$31,MATCH($I23,'App 1'!$B$3:$B$31,0)),IFERROR(INDEX('App 2'!$H$3:$H$11,MATCH($I23,'App 2'!$B$3:$B$11,0)),IFERROR(INDEX(Documentation!$H$3:$H$19,MATCH($I23,Documentation!$B$3:$B$19,0)),"Done"))))="Done","No","Yes")) -> Yes | L23: =IF(AND($H23<>"Done",$K23="No"),ROW(),"")
A24: Phase 8 · Retrospective & asset revision | B24: 8.4 | C24: Revise the ticket template to v1.0 | D24: assets/ticket-template.md is committed at v1.0 with a changelog | E24: 40 | F24: 2 | G24: =IFERROR(INDEX(Config!$E$5:$E$9,MATCH($F24,Config!$D$5:$D$9,0)),0) -> 7 | H24: Not started | I24: 8.2 | K24: =IF($I24="","No",IF(IFERROR(INDEX(Setup!$H$3:$H$62,MATCH($I24,Setup!$B$3:$B$62,0)),IFERROR(INDEX('App 1'!$H$3:$H$31,MATCH($I24,'App 1'!$B$3:$B$31,0)),IFERROR(INDEX('App 2'!$H$3:$H$11,MATCH($I24,'App 2'!$B$3:$B$11,0)),IFERROR(INDEX(Documentation!$H$3:$H$19,MATCH($I24,Documentation!$B$3:$B$19,0)),"Done"))))="Done","No","Yes")) -> Yes | L24: =IF(AND($H24<>"Done",$K24="No"),ROW(),"")
A25: Phase 8 · Retrospective & asset revision | B25: 8.5 | C25: Revise the four agent definitions to v1.0 | D25: All four files (analyst, builder, qa, orchestrator prompt) are committed at v1.0 with changelogs | E25: 60 | F25: 4 | G25: =IFERROR(INDEX(Config!$E$5:$E$9,MATCH($F25,Config!$D$5:$D$9,0)),0) -> 17 | H25: Not started | I25: 8.2 | J25: The orchestrator prompt's four encoded behaviours must still all be present. | K25: =IF($I25="","No",IF(IFERROR(INDEX(Setup!$H$3:$H$62,MATCH($I25,Setup!$B$3:$B$62,0)),IFERROR(INDEX('App 1'!$H$3:$H$31,MATCH($I25,'App 1'!$B$3:$B$31,0)),IFERROR(INDEX('App 2'!$H$3:$H$11,MATCH($I25,'App 2'!$B$3:$B$11,0)),IFERROR(INDEX(Documentation!$H$3:$H$19,MATCH($I25,Documentation!$B$3:$B$19,0)),"Done"))))="Done","No","Yes")) -> Yes | L25: =IF(AND($H25<>"Done",$K25="No"),ROW(),"")
A26: Phase 8 · Retrospective & asset revision | B26: 8.6 | C26: Rewrite design-reference.md properly | D26: The file names 3-5 references with a specific line each, and points at two screens in app #1 that came out generic | E26: 60 | F26: 3 | G26: =IFERROR(INDEX(Config!$E$5:$E$9,MATCH($F26,Config!$D$5:$D$9,0)),0) -> 11 | H26: Not started | I26: 8.2 | J26: §5.3: skills alone give generic-but-slightly-better. Grounding is the fix. | K26: =IF($I26="","No",IF(IFERROR(INDEX(Setup!$H$3:$H$62,MATCH($I26,Setup!$B$3:$B$62,0)),IFERROR(INDEX('App 1'!$H$3:$H$31,MATCH($I26,'App 1'!$B$3:$B$31,0)),IFERROR(INDEX('App 2'!$H$3:$H$11,MATCH($I26,'App 2'!$B$3:$B$11,0)),IFERROR(INDEX(Documentation!$H$3:$H$19,MATCH($I26,Documentation!$B$3:$B$19,0)),"Done"))))="Done","No","Yes")) -> Yes | L26: =IF(AND($H26<>"Done",$K26="No"),ROW(),"")
A27: Phase 8 · Retrospective & asset revision | B27: 8.7 | C27: Write the decisions-log conventions | D27: assets/decisions-log-conventions.md exists and states the mandatory 'because' rule and the ~5/night health signal | E27: 40 | F27: 2 | G27: =IFERROR(INDEX(Config!$E$5:$E$9,MATCH($F27,Config!$D$5:$D$9,0)),0) -> 7 | H27: Not started | I27: 8.1 | J27: §12 Phase 8 deliverable. | K27: =IF($I27="","No",IF(IFERROR(INDEX(Setup!$H$3:$H$62,MATCH($I27,Setup!$B$3:$B$62,0)),IFERROR(INDEX('App 1'!$H$3:$H$31,MATCH($I27,'App 1'!$B$3:$B$31,0)),IFERROR(INDEX('App 2'!$H$3:$H$11,MATCH($I27,'App 2'!$B$3:$B$11,0)),IFERROR(INDEX(Documentation!$H$3:$H$19,MATCH($I27,Documentation!$B$3:$B$19,0)),"Done"))))="Done","No","Yes")) -> Yes | L27: =IF(AND($H27<>"Done",$K27="No"),ROW(),"")
A28: Phase 8 · Retrospective & asset revision | B28: 8.8 | C28: Write the definition-of-done conventions | D28: The ticket template's definition-of-done field has a written standard plus three real examples taken from app #1 | E28: 30 | F28: 2 | G28: =IFERROR(INDEX(Config!$E$5:$E$9,MATCH($F28,Config!$D$5:$D$9,0)),0) -> 7 | H28: Not started | I28: 8.4 | K28: =IF($I28="","No",IF(IFERROR(INDEX(Setup!$H$3:$H$62,MATCH($I28,Setup!$B$3:$B$62,0)),IFERROR(INDEX('App 1'!$H$3:$H$31,MATCH($I28,'App 1'!$B$3:$B$31,0)),IFERROR(INDEX('App 2'!$H$3:$H$11,MATCH($I28,'App 2'!$B$3:$B$11,0)),IFERROR(INDEX(Documentation!$H$3:$H$19,MATCH($I28,Documentation!$B$3:$B$19,0)),"Done"))))="Done","No","Yes")) -> Yes | L28: =IF(AND($H28<>"Done",$K28="No"),ROW(),"")
A29: Phase 8 · Retrospective & asset revision | B29: 8.9 | C29: Write the 'starting a new app' checklist | D29: assets/new-app-checklist.md lists every step from empty repo to first queued ticket, in order | E29: 50 | F29: 3 | G29: =IFERROR(INDEX(Config!$E$5:$E$9,MATCH($F29,Config!$D$5:$D$9,0)),0) -> 11 | H29: Not started | I29: 8.5 | J29: Also needs 8.3 finished. Phase 9 is the test of this file. | K29: =IF($I29="","No",IF(IFERROR(INDEX(Setup!$H$3:$H$62,MATCH($I29,Setup!$B$3:$B$62,0)),IFERROR(INDEX('App 1'!$H$3:$H$31,MATCH($I29,'App 1'!$B$3:$B$31,0)),IFERROR(INDEX('App 2'!$H$3:$H$11,MATCH($I29,'App 2'!$B$3:$B$11,0)),IFERROR(INDEX(Documentation!$H$3:$H$19,MATCH($I29,Documentation!$B$3:$B$19,0)),"Done"))))="Done","No","Yes")) -> Yes | L29: =IF(AND($H29<>"Done",$K29="No"),ROW(),"")
